File: SNI Lab/Lab 1/ERAU Honeycomb Compression.csv
Force (N),Position (mm),Stress (MPa),Strain From Position (Compression) (%)
41.1,0,0.00683,0
43.6,0,0.00725,0
42.1,0,0.007,0
41.7,0,0.00693,0
44.2,0,0.00734,0
53.6,0.0029,0.0089,0.00381
75.4,0.0077,0.0125,0.0101
95.2,0.0116,0.0158,0.0152
108,0.0138,0.018,0.0181
129,0.0171,0.0214,0.0225
164,0.0213,0.0273,0.028
214,0.027,0.0356,0.0355
237,0.0292,0.0394,0.0383
257,0.0315,0.0427,0.0414
320,0.0367,0.0531,0.0482
365,0.0401,0.0607,0.0527
400,0.0427,0.0665,0.0561
459,0.0468,0.0763,0.0615
497,0.0492,0.0826,0.0646
525,0.051,0.0873,0.067
589,0.0549,0.0978,0.0721
654,0.0585,0.109,0.0768
726,0.0623,0.121,0.0818
781,0.0651,0.13,0.0855
840,0.068,0.14,0.0893
945,0.0727,0.157,0.0955
1050,0.0771,0.174,0.101
1130,0.0803,0.187,0.105
1220,0.0838,0.202,0.11
1300,0.0872,0.217,0.115
1390,0.0904,0.232,0.119
1490,0.0938,0.248,0.123
1620,0.0979,0.269,0.129
1710,0.101,0.284,0.132
1820,0.104,0.303,0.137
1890,0.106,0.315,0.14
2010,0.11,0.334,0.144
2120,0.113,0.352,0.148
2200,0.115,0.366,0.151
2340,0.119,0.389,0.157
2450,0.122,0.408,0.161
2560,0.125,0.426,0.165
2720,0.13,0.452,0.17
2850,0.133,0.474,0.175
2990,0.137,0.496,0.18
3110,0.14,0.517,0.184
3210,0.143,0.533,0.188
3340,0.147,0.556,0.193
3480,0.15,0.578,0.197
3630,0.154,0.603,0.202
3730,0.157,0.619,0.206
3840,0.16,0.639,0.21
3940,0.162,0.656,0.213
4100,0.166,0.681,0.218
4270,0.17,0.71,0.223
4390,0.172,0.729,0.226
4540,0.176,0.755,0.231
4720,0.179,0.785,0.235
4880,0.183,0.812,0.24
5080,0.186,0.844,0.245
5240,0.189,0.871,0.249
5430,0.193,0.903,0.253
5610,0.196,0.932,0.258
5770,0.199,0.958,0.262
5980,0.203,0.995,0.267
6180,0.207,1.03,0.271
6360,0.21,1.06,0.276
6510,0.213,1.08,0.279
6680,0.216,1.11,0.283
6780,0.217,1.13,0.285
7010,0.221,1.17,0.291
7210,0.225,1.2,0.295
7380,0.228,1.23,0.299
7590,0.231,1.26,0.304
7780,0.234,1.29,0.308
7970,0.238,1.32,0.312
8160,0.241,1.36,0.316
8380,0.244,1.39,0.321
8590,0.248,1.43,0.326
8830,0.252,1.47,0.331
8950,0.254,1.49,0.334
9190,0.258,1.53,0.339
9440,0.262,1.57,0.344
9600,0.265,1.6,0.348
9800,0.268,1.63,0.352
9980,0.271,1.66,0.356
10100,0.273,1.68,0.358
10300,0.277,1.72,0.363
10500,0.279,1.74,0.367
10700,0.283,1.78,0.371
10900,0.286,1.81,0.376
11100,0.289,1.84,0.38
11400,0.293,1.89,0.385
11600,0.296,1.92,0.389
11700,0.3,1.95,0.393
12000,0.304,1.99,0.399
12200,0.307,2.03,0.403
12400,0.31,2.06,0.407
12600,0.314,2.1,0.412
12900,0.318,2.14,0.417
13000,0.32,2.17,0.421
13200,0.324,2.2,0.425
13400,0.326,2.23,0.429
13600,0.329,2.26,0.432
13800,0.333,2.29,0.437
14000,0.336,2.32,0.441
14200,0.339,2.36,0.445
14400,0.342,2.4,0.45
14600,0.345,2.42,0.453
14800,0.349,2.46,0.458
15000,0.352,2.49,0.462
15200,0.355,2.53,0.467
15500,0.36,2.57,0.472
15700,0.364,2.61,0.477
15900,0.367,2.64,0.481
16100,0.37,2.68,0.486
16300,0.373,2.71,0.49
16500,0.376,2.74,0.494
16700,0.38,2.78,0.499
16900,0.382,2.81,0.502
17100,0.386,2.84,0.507
17300,0.389,2.87,0.51
17400,0.391,2.89,0.514
17600,0.395,2.93,0.518
17900,0.398,2.97,0.523
18000,0.401,2.99,0.527
18300,0.405,3.04,0.532
18500,0.409,3.08,0.537
18700,0.412,3.1,0.541
18900,0.416,3.15,0.546
19100,0.419,3.18,0.551
19300,0.422,3.2,0.554
19500,0.426,3.24,0.559
19700,0.429,3.28,0.564
19900,0.432,3.3,0.567
20100,0.436,3.33,0.572
20200,0.438,3.36,0.575
20400,0.442,3.39,0.58
20600,0.445,3.42,0.584
20700,0.447,3.44,0.587
20900,0.45,3.47,0.592
21000,0.453,3.5,0.595
21300,0.457,3.53,0.6
21500,0.461,3.57,0.606
21600,0.464,3.59,0.609
21800,0.468,3.63,0.614
22100,0.472,3.67,0.62
22200,0.474,3.69,0.623
22400,0.478,3.72,0.628
22600,0.482,3.75,0.633
22800,0.486,3.79,0.638
22900,0.489,3.81,0.642
23000,0.492,3.83,0.646
23100,0.493,3.84,0.648
23300,0.498,3.88,0.653
23500,0.501,3.91,0.658
23600,0.504,3.93,0.661
23900,0.508,3.97,0.668
24000,0.511,3.98,0.671
24100,0.514,4.01,0.676
24300,0.519,4.04,0.681
24500,0.522,4.07,0.686
24600,0.525,4.08,0.689
24700,0.529,4.11,0.694
24900,0.533,4.14,0.699
25000,0.535,4.15,0.703
25100,0.539,4.17,0.708
25200,0.543,4.19,0.713
25200,0.545,4.19,0.716
17000,0.554,2.83,0.727
16800,0.555,2.79,0.729
16900,0.559,2.82,0.734
16900,0.562,2.81,0.738
16900,0.565,2.8,0.742
16800,0.568,2.8,0.746
16700,0.573,2.77,0.752
16500,0.576,2.75,0.757
16400,0.58,2.73,0.762
16200,0.584,2.7,0.767
16000,0.586,2.66,0.77
15900,0.591,2.64,0.776
15700,0.594,2.61,0.78
15400,0.597,2.57,0.784
14800,0.601,2.46,0.789
9170,0.607,1.52,0.797
9290,0.609,1.54,0.8
9420,0.612,1.57,0.804
9500,0.615,1.58,0.808
9590,0.618,1.59,0.812
9650,0.622,1.6,0.817
9690,0.625,1.61,0.821
9690,0.629,1.61,0.825
9720,0.633,1.62,0.831
9750,0.636,1.62,0.836
9720,0.639,1.62,0.839
9730,0.642,1.62,0.844
9780,0.647,1.63,0.849
9750,0.649,1.62,0.852
9780,0.653,1.63,0.857
9790,0.656,1.63,0.861
9790,0.659,1.63,0.865
9800,0.661,1.63,0.868
9810,0.665,1.63,0.873
9800,0.668,1.63,0.877
9760,0.67,1.62,0.88
9770,0.674,1.62,0.885
9760,0.677,1.62,0.889
9730,0.68,1.62,0.893
9760,0.684,1.62,0.898
9770,0.688,1.62,0.904
9720,0.691,1.62,0.907
9730,0.695,1.62,0.913
9720,0.698,1.61,0.917
9720,0.701,1.62,0.921
9730,0.705,1.62,0.926
9750,0.708,1.62,0.93
9710,0.711,1.61,0.934
9720,0.714,1.62,0.938
9720,0.717,1.62,0.942
9760,0.721,1.62,0.947
9790,0.724,1.63,0.951
9760,0.727,1.62,0.954
9770,0.73,1.62,0.959
9810,0.734,1.63,0.963
9810,0.737,1.63,0.968
9800,0.741,1.63,0.973
9830,0.744,1.63,0.977
9810,0.748,1.63,0.982
9820,0.751,1.63,0.987
9850,0.754,1.64,0.991
9860,0.758,1.64,0.995
9890,0.762,1.64,1
9890,0.765,1.64,1
9880,0.768,1.64,1.01
9910,0.771,1.65,1.01
9880,0.773,1.64,1.01
9920,0.777,1.65,1.02
9930,0.78,1.65,1.02
9950,0.783,1.65,1.03
10000,0.787,1.66,1.03
10000,0.79,1.66,1.04
10000,0.793,1.67,1.04
10000,0.797,1.67,1.05
10000,0.8,1.67,1.05
10000,0.804,1.67,1.06
10100,0.807,1.67,1.06
10100,0.81,1.68,1.06
10100,0.814,1.67,1.07
10100,0.818,1.68,1.07
10100,0.821,1.69,1.08
10100,0.824,1.69,1.08
10200,0.827,1.69,1.09
10200,0.829,1.69,1.09
10200,0.833,1.7,1.09
10200,0.836,1.7,1.1
10200,0.839,1.7,1.1
10300,0.843,1.71,1.11
10300,0.845,1.7,1.11
10300,0.85,1.71,1.12
10300,0.853,1.72,1.12
10400,0.856,1.72,1.12
10400,0.86,1.73,1.13
10400,0.864,1.73,1.13
10400,0.866,1.73,1.14
10400,0.87,1.73,1.14
10500,0.874,1.74,1.15
10500,0.877,1.75,1.15
10500,0.88,1.75,1.16
10500,0.883,1.75,1.16
10600,0.886,1.76,1.16
10600,0.889,1.76,1.17
10600,0.892,1.76,1.17
10600,0.896,1.77,1.18
10700,0.899,1.77,1.18
10700,0.902,1.77,1.18
10700,0.906,1.78,1.19
10800,0.91,1.79,1.19
10700,0.913,1.79,1.2
10800,0.916,1.79,1.2
10800,0.92,1.79,1.21
10800,0.923,1.8,1.21
10800,0.927,1.8,1.22
10900,0.93,1.81,1.22
10900,0.933,1.81,1.23
10900,0.936,1.81,1.23
10900,0.939,1.82,1.23
11000,0.943,1.82,1.24
11000,0.945,1.82,1.24
11000,0.948,1.82,1.24
11000,0.952,1.83,1.25
11000,0.955,1.84,1.25
11000,0.958,1.83,1.26
11100,0.962,1.84,1.26
11100,0.965,1.85,1.27
11100,0.969,1.85,1.27
11100,0.973,1.85,1.28
11200,0.976,1.86,1.28
11200,0.98,1.86,1.29
11200,0.984,1.87,1.29
11300,0.987,1.87,1.3
11300,0.99,1.87,1.3
11300,0.993,1.88,1.3
11300,0.995,1.88,1.31
11300,0.999,1.88,1.31
11400,1,1.89,1.32
11400,1.01,1.89,1.32
11400,1.01,1.9,1.33
11500,1.01,1.9,1.33
11500,1.02,1.91,1.33
11500,1.02,1.91,1.34
11500,1.02,1.92,1.34
11500,1.03,1.92,1.35
11500,1.03,1.92,1.35
11600,1.03,1.93,1.36
11600,1.04,1.93,1.36
11600,1.04,1.93,1.37
11700,1.04,1.94,1.37
11700,1.05,1.94,1.37
11700,1.05,1.94,1.38
11700,1.05,1.95,1.38
11700,1.06,1.95,1.39
11700,1.06,1.95,1.39
11800,1.06,1.96,1.39
11800,1.07,1.96,1.4
11800,1.07,1.96,1.4
11800,1.07,1.97,1.41
11800,1.08,1.97,1.41
11900,1.08,1.98,1.42
11900,1.08,1.98,1.42
11900,1.09,1.98,1.43
12000,1.09,1.99,1.43
12000,1.09,1.99,1.44
12000,1.1,1.99,1.44
12000,1.1,2,1.44
12000,1.1,2,1.45
12000,1.11,2,1.45
12100,1.11,2.01,1.46
12100,1.11,2.01,1.46
12100,1.11,2.01,1.46
12100,1.12,2.01,1.47
12100,1.12,2.02,1.47
12200,1.12,2.02,1.48
12200,1.13,2.03,1.48
12200,1.13,2.03,1.49
12300,1.14,2.04,1.49
12200,1.14,2.04,1.5
12300,1.14,2.04,1.5
12300,1.15,2.05,1.51
12300,1.15,2.05,1.51
12300,1.15,2.05,1.51
12400,1.16,2.06,1.52
12400,1.16,2.06,1.52
12400,1.16,2.06,1.53
12400,1.17,2.07,1.53
12500,1.17,2.07,1.53
12500,1.17,2.07,1.54
12500,1.17,2.07,1.54
12500,1.18,2.08,1.55
12600,1.18,2.09,1.55
12500,1.18,2.09,1.56
12600,1.19,2.09,1.56
12600,1.19,2.1,1.57
12700,1.2,2.1,1.57
12700,1.2,2.1,1.58
12700,1.2,2.11,1.58
12700,1.21,2.12,1.59
12700,1.21,2.12,1.59
12800,1.21,2.12,1.59
12700,1.22,2.12,1.6
12800,1.22,2.13,1.6
12800,1.22,2.13,1.6
12800,1.22,2.13,1.61
12900,1.23,2.14,1.61
12900,1.23,2.14,1.62
12900,1.23,2.14,1.62
12900,1.24,2.15,1.63
12900,1.24,2.15,1.63
12900,1.25,2.15,1.64
12900,1.25,2.15,1.64
12900,1.25,2.15,1.65
13000,1.26,2.16,1.65
13000,1.26,2.16,1.65
13000,1.26,2.16,1.66
13000,1.27,2.16,1.66
13000,1.27,2.16,1.67
13000,1.27,2.16,1.67
13100,1.28,2.17,1.68
13100,1.28,2.17,1.68
13100,1.28,2.17,1.68
13100,1.29,2.18,1.69
13100,1.29,2.18,1.69
13100,1.29,2.18,1.7
13100,1.3,2.18,1.7
13100,1.3,2.18,1.71
13100,1.3,2.18,1.71
13100,1.31,2.18,1.72
13100,1.31,2.19,1.72
13200,1.31,2.19,1.73
13200,1.32,2.19,1.73
13200,1.32,2.19,1.73
13200,1.32,2.19,1.74
13200,1.33,2.19,1.74
13200,1.33,2.19,1.74
13200,1.33,2.2,1.75
13200,1.34,2.2,1.75
13200,1.34,2.2,1.76
13300,1.34,2.21,1.76
13300,1.35,2.21,1.77
13300,1.35,2.21,1.77
13300,1.35,2.21,1.78
13300,1.36,2.21,1.78
13300,1.36,2.21,1.78
13300,1.36,2.21,1.79
13300,1.37,2.22,1.79
13300,1.37,2.21,1.8
13300,1.37,2.22,1.8
13400,1.38,2.22,1.81
13400,1.38,2.22,1.81
13400,1.38,2.23,1.82
13400,1.38,2.22,1.82
13400,1.39,2.23,1.82
13400,1.39,2.23,1.83
13400,1.39,2.23,1.83
13400,1.4,2.23,1.84
13400,1.4,2.23,1.84
13400,1.41,2.23,1.85
13400,1.41,2.23,1.85
13400,1.41,2.23,1.86
13400,1.42,2.23,1.86
13400,1.42,2.23,1.86
13400,1.42,2.23,1.87
13400,1.43,2.22,1.87
13400,1.43,2.22,1.88
13400,1.43,2.22,1.88
13300,1.44,2.22,1.89
13300,1.44,2.21,1.89
13300,1.44,2.21,1.89
13300,1.45,2.21,1.9
13300,1.45,2.21,1.9
13300,1.45,2.2,1.91
13200,1.46,2.2,1.91
13200,1.46,2.2,1.92
13200,1.46,2.19,1.92
13200,1.47,2.2,1.93
13200,1.47,2.2,1.93
13200,1.47,2.19,1.93
13100,1.48,2.18,1.94
13100,1.48,2.18,1.94
13100,1.48,2.17,1.95
13100,1.49,2.17,1.95
13100,1.49,2.17,1.96
13000,1.49,2.16,1.96
13000,1.5,2.16,1.96
13000,1.5,2.16,1.97
13000,1.5,2.16,1.97
13000,1.51,2.16,1.98
12900,1.51,2.15,1.98
12900,1.51,2.14,1.99
12900,1.52,2.15,1.99
12900,1.52,2.14,2
12800,1.52,2.13,2
12800,1.53,2.13,2.01
12800,1.53,2.12,2.01
12800,1.53,2.12,2.01
12700,1.54,2.11,2.02
12700,1.54,2.11,2.02
12600,1.54,2.1,2.03
12600,1.55,2.1,2.03
12600,1.55,2.09,2.03
12600,1.55,2.09,2.04
12500,1.55,2.08,2.04
12500,1.56,2.08,2.05
12500,1.56,2.07,2.05
12400,1.56,2.06,2.05
12400,1.57,2.06,2.06
12400,1.57,2.06,2.06
12300,1.58,2.05,2.07
12300,1.58,2.05,2.07
12300,1.58,2.04,2.08
12200,1.59,2.03,2.08
12200,1.59,2.03,2.09
12200,1.59,2.03,2.09
12100,1.6,2.01,2.1
12100,1.6,2.01,2.1
12100,1.6,2.01,2.11
12000,1.61,2,2.11
12100,1.61,2.01,2.11
12000,1.61,1.99,2.12
12000,1.62,1.99,2.12
11900,1.62,1.98,2.13
11900,1.62,1.98,2.13
11900,1.63,1.97,2.14
11800,1.63,1.97,2.14
11800,1.63,1.96,2.14
11700,1.64,1.95,2.15
11700,1.64,1.95,2.15
11700,1.64,1.94,2.16
11600,1.65,1.93,2.16
11600,1.65,1.93,2.17
11600,1.65,1.92,2.17
11500,1.66,1.91,2.18
11500,1.66,1.91,2.18
11400,1.66,1.9,2.18
11400,1.67,1.9,2.19
11400,1.67,1.89,2.19
11400,1.67,1.89,2.2
11300,1.68,1.89,2.2
11300,1.68,1.87,2.2
11300,1.68,1.88,2.21
11200,1.69,1.87,2.21
11200,1.69,1.86,2.22
11200,1.69,1.85,2.22
11100,1.7,1.85,2.23
11100,1.7,1.85,2.23
11100,1.7,1.84,2.24
11000,1.71,1.83,2.24
11000,1.71,1.83,2.25
11000,1.71,1.82,2.25
10900,1.72,1.82,2.25
10900,1.72,1.82,2.26
10900,1.72,1.81,2.26
10900,1.73,1.81,2.27
10800,1.73,1.8,2.27
10800,1.73,1.8,2.28
10800,1.73,1.79,2.28
10700,1.74,1.79,2.28
10700,1.74,1.79,2.29
10700,1.75,1.78,2.29
10600,1.75,1.77,2.3
10600,1.75,1.76,2.3
10600,1.76,1.76,2.31
10500,1.76,1.75,2.31
10500,1.76,1.75,2.32
10500,1.77,1.74,2.32
10500,1.77,1.74,2.32
10400,1.77,1.74,2.33
10400,1.78,1.73,2.33
10400,1.78,1.73,2.34
10300,1.78,1.72,2.34
10300,1.79,1.72,2.34
10300,1.79,1.71,2.35
10300,1.79,1.7,2.35
10300,1.8,1.7,2.36
10200,1.8,1.7,2.36
10200,1.8,1.69,2.37
10100,1.81,1.69,2.37
10100,1.81,1.68,2.38
10100,1.81,1.68,2.38
10100,1.82,1.67,2.39
10100,1.82,1.67,2.39
10000,1.82,1.66,2.39
10000,1.83,1.66,2.4
9970,1.83,1.66,2.4
9950,1.83,1.65,2.41
9950,1.84,1.65,2.41
9920,1.84,1.65,2.41
9890,1.84,1.64,2.42
9890,1.85,1.64,2.42
9860,1.85,1.64,2.43
9830,1.85,1.63,2.43
9830,1.86,1.63,2.44
9770,1.86,1.62,2.44
9730,1.86,1.62,2.45
9740,1.87,1.62,2.45
9690,1.87,1.61,2.46
9660,1.87,1.61,2.46
9650,1.88,1.6,2.47
9630,1.88,1.6,2.47
9600,1.88,1.6,2.47
9600,1.89,1.6,2.48
9560,1.89,1.59,2.48
9530,1.89,1.58,2.48
9520,1.89,1.58,2.49
9500,1.9,1.58,2.49
9470,1.9,1.57,2.5
9470,1.91,1.57,2.5
9440,1.91,1.57,2.51
9410,1.91,1.56,2.51
9370,1.92,1.56,2.52
9340,1.92,1.55,2.52
9350,1.92,1.55,2.53
9320,1.93,1.55,2.53
9290,1.93,1.54,2.53
9270,1.93,1.54,2.54
9240,1.94,1.54,2.54
9230,1.94,1.53,2.55
9250,1.94,1.54,2.55
9220,1.94,1.53,2.55
9220,1.95,1.53,2.56
9190,1.95,1.53,2.56
9170,1.96,1.52,2.57
9150,1.96,1.52,2.57
9120,1.96,1.52,2.58
9090,1.97,1.51,2.58
9110,1.97,1.51,2.59
9070,1.97,1.51,2.59
9030,1.98,1.5,2.59
9060,1.98,1.51,2.6
9030,1.98,1.5,2.6
8990,1.99,1.49,2.61
8990,1.99,1.49,2.61
8970,1.99,1.49,2.62
8950,1.99,1.49,2.62
8950,2,1.49,2.62
8930,2,1.48,2.63
8670,2.11,1.44,2.77
8540,2.19,1.42,2.88
8580,2.28,1.43,2.99
8810,2.36,1.47,3.1
9260,2.45,1.54,3.21
9810,2.53,1.63,3.32
10500,2.61,1.74,3.43
11100,2.69,1.84,3.54
11700,2.78,1.95,3.65
12300,2.86,2.04,3.75
12700,2.94,2.11,3.87
12800,3.03,2.13,3.97
12700,3.11,2.12,4.09
12400,3.19,2.06,4.19
12000,3.28,2,4.31
11700,3.36,1.95,4.41
11400,3.45,1.89,4.53
11200,3.53,1.86,4.63
11000,3.61,1.83,4.74
10900,3.69,1.81,4.85
10900,3.78,1.81,4.96
10900,3.86,1.81,5.07
11000,3.95,1.83,5.18
11200,4.02,1.86,5.29
11400,4.11,1.9,5.4
11600,4.19,1.93,5.5
11800,4.28,1.96,5.62
12000,4.36,1.99,5.72
12000,4.44,1.99,5.84
11900,4.52,1.98,5.94
11700,4.61,1.94,6.06
11400,4.69,1.89,6.16
11000,4.78,1.83,6.28
10700,4.86,1.78,6.38
10400,4.94,1.73,6.49
10300,5.02,1.72,6.6
10400,5.11,1.72,6.71
10500,5.19,1.74,6.82
10600,5.28,1.77,6.93
10900,5.36,1.81,7.04
11200,5.44,1.87,7.15
11600,5.52,1.92,7.25
11900,5.61,1.98,7.37
12100,5.69,2.01,7.47
12300,5.78,2.04,7.59
12300,5.86,2.04,7.69
12200,5.94,2.02,7.81
12000,6.02,1.99,7.91
11800,6.11,1.96,8.02
11500,6.19,1.91,8.13
11300,6.28,1.88,8.24
11200,6.36,1.86,8.35
11000,6.44,1.83,8.46
11000,6.52,1.82,8.57
11000,6.61,1.83,8.68
11000,6.69,1.83,8.78
11100,6.78,1.85,8.9
11300,6.86,1.88,9
11500,6.94,1.91,9.12
11600,7.02,1.93,9.22
11700,7.11,1.94,9.34
11700,7.19,1.95,9.44
11600,7.28,1.94,9.55
11500,7.36,1.9,9.66
11300,7.44,1.88,9.77
11100,7.52,1.85,9.88
11000,7.61,1.82,9.99
10800,7.69,1.8,10.1
10800,7.78,1.8,10.2
10900,7.86,1.81,10.3
11000,7.94,1.83,10.4
11200,8.02,1.86,10.5
11400,8.11,1.9,10.6
11700,8.19,1.94,10.8
11900,8.27,1.98,10.9
12100,8.36,2.01,11
12200,8.44,2.03,11.1
12300,8.52,2.04,11.2
12300,8.61,2.04,11.3
12100,8.69,2.02,11.4
11900,8.78,1.98,11.5
11600,8.86,1.94,11.6
11400,8.94,1.9,11.7
11200,9.02,1.87,11.8
11200,9.11,1.85,12
11100,9.19,1.85,12.1
11100,9.28,1.85,12.2
11200,9.35,1.86,12.3
11200,9.44,1.87,12.4
11300,9.52,1.88,12.5
11400,9.61,1.9,12.6
11600,9.69,1.92,12.7
11700,9.77,1.94,12.8
11700,9.85,1.94,12.9
11700,9.94,1.95,13.1
11600,10,1.94,13.2
11600,10.1,1.92,13.3
11500,10.2,1.9,13.4
11400,10.3,1.89,13.5
11300,10.4,1.88,13.6
11200,10.4,1.86,13.7
11100,10.5,1.85,13.8
11100,10.6,1.85,13.9
11100,10.7,1.85,14
11200,10.8,1.86,14.2
11200,10.9,1.87,14.3
11400,10.9,1.89,14.4
11500,11,1.92,14.5
11700,11.1,1.95,14.6
11800,11.2,1.96,14.7
11900,11.3,1.97,14.8
11900,11.4,1.98,14.9
11900,11.4,1.99,15
12000,11.5,1.99,15.1
12000,11.6,1.99,15.2
11900,11.7,1.98,15.3
11800,11.8,1.96,15.5
11700,11.9,1.94,15.6
11600,11.9,1.92,15.7
11500,12,1.9,15.8
11400,12.1,1.9,15.9
11400,12.2,1.9,16
11400,12.3,1.9,16.1
11400,12.4,1.89,16.2
11400,12.4,1.89,16.3
11500,12.5,1.9,16.4
11500,12.6,1.92,16.6
11600,12.7,1.92,16.7
11600,12.8,1.93,16.8
11600,12.9,1.93,16.9
11600,12.9,1.93,17
11600,13,1.92,17.1
11600,13.1,1.92,17.2
11500,13.2,1.92,17.3
11500,13.3,1.92,17.4
11500,13.4,1.91,17.5
11600,13.4,1.93,17.7
11700,13.5,1.95,17.8
11800,13.6,1.96,17.9
11900,13.7,1.97,18
11800,13.8,1.97,18.1
11800,13.9,1.97,18.2
11900,13.9,1.98,18.3
11900,14,1.98,18.4
11900,14.1,1.98,18.5
11900,14.2,1.98,18.6
11900,14.3,1.97,18.7
11700,14.4,1.95,18.9
11700,14.4,1.95,19
11700,14.5,1.94,19.1
11700,14.6,1.94,19.2
11600,14.7,1.94,19.3
11700,14.8,1.94,19.4
11700,14.9,1.94,19.5
11700,14.9,1.94,19.6
11600,15,1.92,19.7
11400,15.1,1.9,19.8
11300,15.2,1.89,19.9
11300,15.3,1.88,20.1
11300,15.4,1.88,20.2
11400,15.4,1.89,20.3
11300,15.5,1.89,20.4
11400,15.6,1.89,20.5
11300,15.7,1.89,20.6
11400,15.8,1.9,20.7
11500,15.9,1.91,20.8
11600,15.9,1.92,20.9
11600,16,1.93,21
11700,16.1,1.94,21.2
11700,16.2,1.95,21.3
11800,16.3,1.96,21.4
11800,16.4,1.96,21.5
11800,16.4,1.96,21.6
11800,16.5,1.97,21.7
11900,16.6,1.97,21.8
11800,16.7,1.97,21.9
11800,16.8,1.96,22
11800,16.9,1.95,22.1
11800,16.9,1.95,22.2
11700,17,1.95,22.4
11700,17.1,1.95,22.5
11700,17.2,1.94,22.6
11600,17.3,1.93,22.7
11600,17.4,1.93,22.8
11600,17.4,1.93,22.9
11700,17.5,1.94,23
11700,17.6,1.95,23.1
11800,17.7,1.95,23.2
11800,17.8,1.96,23.3
11700,17.9,1.94,23.4
11600,17.9,1.92,23.6
11500,18,1.91,23.7
11500,18.1,1.9,23.8
11400,18.2,1.9,23.9
11400,18.3,1.9,24
11400,18.4,1.9,24.1
11500,18.4,1.91,24.2
11500,18.5,1.92,24.3
11600,18.6,1.93,24.4
11700,18.7,1.95,24.5
11800,18.8,1.96,24.7
11800,18.9,1.96,24.8
11800,18.9,1.96,24.9
11700,19,1.95,25
11700,19.1,1.94,25.1
11700,19.2,1.94,25.2
11700,19.3,1.94,25.3
11700,19.4,1.94,25.4
11700,19.4,1.95,25.5
11700,19.5,1.95,25.6
11800,19.6,1.96,25.7
11900,19.7,1.97,25.9
11900,19.8,1.98,26
11900,19.9,1.98,26.1
11900,19.9,1.98,26.2
11900,20,1.98,26.3
11900,20.1,1.97,26.4
11800,20.2,1.96,26.5
11700,20.3,1.95,26.6
11600,20.4,1.93,26.7
11500,20.4,1.92,26.8
11400,20.5,1.9,26.9
11400,20.6,1.9,27.1
11400,20.7,1.89,27.2
11400,20.8,1.89,27.3
11400,20.9,1.89,27.4
11500,20.9,1.9,27.5
11500,21,1.91,27.6
11500,21.1,1.92,27.7
11600,21.2,1.92,27.8
11600,21.3,1.93,27.9
11600,21.4,1.94,28
11600,21.4,1.93,28.2
11500,21.5,1.91,28.3
11500,21.6,1.91,28.4
11400,21.7,1.9,28.5
11400,21.8,1.89,28.6
11300,21.9,1.88,28.7
11300,21.9,1.89,28.8
11400,22,1.89,28.9
11400,22.1,1.89,29
11500,22.2,1.91,29.1
11600,22.3,1.93,29.3
11800,22.4,1.95,29.4
12000,22.4,1.99,29.5
12100,22.5,2.01,29.6
12200,22.6,2.03,29.7
12300,22.7,2.05,29.8
12400,22.8,2.06,29.9
12400,22.9,2.06,30
12300,22.9,2.05,30.1
12200,23,2.03,30.2
12100,23.1,2.01,30.3
12000,23.2,1.99,30.5
11900,23.3,1.97,30.6
11800,23.4,1.95,30.7
11700,23.4,1.95,30.8
11600,23.5,1.93,30.9
11600,23.6,1.93,31
11700,23.7,1.94,31.1
11700,23.8,1.94,31.2
11700,23.9,1.95,31.3
11800,23.9,1.96,31.4
11800,24,1.97,31.5
11900,24.1,1.97,31.7
11900,24.2,1.98,31.8
12000,24.3,1.99,31.9
12000,24.4,1.99,32
12000,24.4,1.99,32.1
12000,24.5,1.99,32.2
11900,24.6,1.98,32.3
11800,24.7,1.96,32.4
11700,24.8,1.95,32.5
11700,24.9,1.94,32.6
11700,24.9,1.94,32.8
11700,25,1.95,32.9
11800,25.1,1.97,33
12000,25.2,1.99,33.1
12100,25.3,2.01,33.2
12200,25.4,2.02,33.3
12200,25.4,2.03,33.4
12200,25.5,2.03,33.5
12200,25.6,2.03,33.6
12200,25.7,2.02,33.7
12100,25.8,2.02,33.8
12100,25.9,2.01,34
11900,25.9,1.98,34.1
11800,26,1.96,34.2
11800,26.1,1.95,34.3
11700,26.2,1.94,34.4
11600,26.3,1.93,34.5
11600,26.4,1.93,34.6
11700,26.4,1.94,34.7
11700,26.5,1.95,34.8
11700,26.6,1.95,34.9
11700,26.7,1.95,35
11700,26.8,1.94,35.2
11700,26.9,1.94,35.3
11700,26.9,1.95,35.4
11700,27,1.95,35.5
11700,27.1,1.95,35.6
11700,27.2,1.94,35.7
11600,27.3,1.93,35.8
11600,27.4,1.92,35.9
11600,27.4,1.92,36
11500,27.5,1.92,36.1
11600,27.6,1.92,36.3
11600,27.7,1.93,36.4
11600,27.8,1.93,36.5
11700,27.9,1.94,36.6
11700,27.9,1.95,36.7
11700,28,1.95,36.8
11800,28.1,1.97,36.9
11900,28.2,1.97,37
11900,28.3,1.98,37.1
11900,28.4,1.97,37.2
11900,28.4,1.98,37.3
11900,28.5,1.98,37.5
11900,28.6,1.97,37.6
11900,28.7,1.97,37.7
11800,28.8,1.96,37.8
11700,28.9,1.95,37.9
11800,28.9,1.95,38
11700,29,1.95,38.1
11700,29.1,1.94,38.2
11600,29.2,1.93,38.3
11600,29.3,1.92,38.4
11500,29.4,1.92,38.5
11500,29.4,1.92,38.7
11600,29.5,1.92,38.8
11600,29.6,1.93,38.9
11700,29.7,1.94,39
11700,29.8,1.95,39.1
11700,29.9,1.94,39.2
11700,29.9,1.94,39.3
11600,30,1.93,39.4
11600,30.1,1.93,39.5
11600,30.2,1.92,39.6
11500,30.3,1.92,39.8
11500,30.4,1.91,39.9
11600,30.4,1.92,40
11700,30.5,1.94,40.1
11800,30.6,1.96,40.2
11900,30.7,1.97,40.3
11900,30.8,1.98,40.4
11900,30.9,1.98,40.5
11900,30.9,1.98,40.6
12000,31,1.99,40.7
12100,31.1,2.01,40.9
12100,31.2,2.02,41
12100,31.3,2.02,41.1
12100,31.4,2.01,41.2
12100,31.4,2.01,41.3
12000,31.5,2,41.4
11900,31.6,1.99,41.5
11800,31.7,1.97,41.6
11800,31.8,1.96,41.7
11800,31.9,1.95,41.8
11700,31.9,1.95,41.9
11800,32,1.95,42.1
11800,32.1,1.96,42.2
11800,32.2,1.96,42.3
11800,32.3,1.96,42.4
11800,32.4,1.95,42.5
11700,32.4,1.95,42.6
11700,32.5,1.94,42.7
11700,32.6,1.95,42.8
11700,32.7,1.95,42.9
11700,32.8,1.95,43
11700,32.9,1.94,43.1
11600,32.9,1.94,43.3
11600,33,1.93,43.4
11600,33.1,1.93,43.5
11600,33.2,1.93,43.6
11600,33.3,1.93,43.7
11600,33.4,1.94,43.8
11700,33.4,1.95,43.9
11700,33.5,1.95,44
11800,33.6,1.96,44.1
11800,33.7,1.96,44.2
11900,33.8,1.98,44.4
11900,33.9,1.98,44.5
11900,33.9,1.98,44.6
11900,34,1.97,44.7
11800,34.1,1.96,44.8
11800,34.2,1.96,44.9
11800,34.3,1.96,45
11800,34.4,1.97,45.1
11900,34.4,1.97,45.2
11900,34.5,1.98,45.3
11900,34.6,1.98,45.4
11900,34.7,1.98,45.6
11800,34.8,1.96,45.7
11700,34.9,1.94,45.8
11600,34.9,1.92,45.9
11500,35,1.92,46
11500,35.1,1.92,46.1
11500,35.2,1.92,46.2
11500,35.3,1.92,46.3
11600,35.4,1.92,46.4
11600,35.4,1.93,46.5
11700,35.5,1.94,46.6
11800,35.6,1.96,46.8
11800,35.7,1.96,46.9
11900,35.8,1.97,47
11800,35.9,1.97,47.1
11800,35.9,1.96,47.2
11800,36,1.96,47.3
11800,36.1,1.96,47.4
11700,36.2,1.94,47.5
11600,36.3,1.93,47.6
11600,36.4,1.93,47.7
11600,36.4,1.93,47.9
11600,36.5,1.93,48
11600,36.6,1.93,48.1
11600,36.7,1.93,48.2
11700,36.8,1.94,48.3
11700,36.9,1.95,48.4
11800,36.9,1.96,48.5
11900,37,1.97,48.6
11900,37.1,1.98,48.7
11900,37.2,1.99,48.8
12000,37.3,2,49
12100,37.4,2,49.1
12100,37.4,2.02,49.2
12100,37.5,2.02,49.3
12100,37.6,2.01,49.4
11900,37.7,1.98,49.5
11800,37.8,1.95,49.6
11600,37.9,1.93,49.7
11500,37.9,1.92,49.8
11500,38,1.9,49.9
11400,38.1,1.89,50
11400,38.2,1.89,50.2
11400,38.3,1.9,50.3
11400,38.4,1.9,50.4
11500,38.4,1.91,50.5
11600,38.5,1.93,50.6
11700,38.6,1.94,50.7
11700,38.7,1.95,50.8
11900,38.8,1.97,50.9
11900,38.9,1.98,51
11900,38.9,1.98,51.1
11900,39,1.98,51.2
11900,39.1,1.97,51.4
11800,39.2,1.96,51.5
11700,39.3,1.95,51.6
11700,39.4,1.95,51.7
11700,39.4,1.94,51.8
11600,39.5,1.94,51.9
11600,39.6,1.93,52
11600,39.7,1.93,52.1
11600,39.8,1.93,52.2
11600,39.9,1.93,52.3
11700,39.9,1.95,52.5
11800,40,1.96,52.6
11900,40.1,1.97,52.7
11900,40.2,1.99,52.8
12000,40.3,1.99,52.9
12000,40.4,1.99,53
12000,40.4,1.99,53.1
11900,40.5,1.98,53.2
11900,40.6,1.97,53.3
11800,40.7,1.96,53.4
11700,40.8,1.95,53.5
11600,40.9,1.94,53.7
11600,40.9,1.93,53.8
11500,41,1.91,53.9
11500,41.1,1.9,54
11400,41.2,1.89,54.1
11400,41.3,1.89,54.2
11400,41.4,1.9,54.3
11500,41.4,1.92,54.4
11600,41.5,1.92,54.5
11700,41.6,1.94,54.6
11800,41.7,1.95,54.7
11900,41.8,1.97,54.9
12000,41.9,1.99,55
12100,41.9,2.01,55.1
12100,42,2.01,55.2
12100,42.1,2.01,55.3
12100,42.2,2.01,55.4
12100,42.3,2.01,55.5
12100,42.4,2.01,55.6
12000,42.4,2,55.7
11900,42.5,1.98,55.8
11900,42.6,1.97,56
11800,42.7,1.97,56.1
11800,42.8,1.97,56.2
11800,42.9,1.96,56.3
11800,42.9,1.97,56.4
11900,43,1.98,56.5
11900,43.1,1.99,56.6
12000,43.2,1.99,56.7
12100,43.3,2.01,56.8
12100,43.4,2.01,56.9
12100,43.4,2.01,57.1
12100,43.5,2,57.2
12000,43.6,1.99,57.3
11900,43.7,1.97,57.4
11800,43.8,1.96,57.5
11700,43.9,1.94,57.6
11600,43.9,1.93,57.7
11600,44,1.92,57.8
11500,44.1,1.92,57.9
11500,44.2,1.91,58
11500,44.3,1.91,58.1
11500,44.4,1.91,58.3
11500,44.4,1.92,58.4
11600,44.5,1.92,58.5
11600,44.6,1.93,58.6
11600,44.7,1.92,58.7
11600,44.8,1.93,58.8
11600,44.9,1.93,58.9
11600,44.9,1.93,59
11600,45,1.92,59.1
11600,45.1,1.93,59.2
11700,45.2,1.94,59.3
11700,45.3,1.95,59.5
11700,45.4,1.95,59.6
11800,45.4,1.96,59.7
11800,45.5,1.97,59.8
11800,45.6,1.97,59.9
11700,45.7,1.95,60
11700,45.8,1.94,60.1
11600,45.9,1.93,60.2
11600,45.9,1.93,60.3
11600,46,1.93,60.4
11700,46.1,1.94,60.6
11700,46.2,1.95,60.7
11800,46.3,1.97,60.8
11900,46.4,1.98,60.9
12000,46.4,2,61
12100,46.5,2.01,61.1
12200,46.6,2.02,61.2
12200,46.7,2.02,61.3
12100,46.8,2.01,61.4
12100,46.9,2.01,61.5
12100,46.9,2,61.6
12000,47,2,61.8
12000,47.1,2,61.9
11900,47.2,1.98,62
11900,47.3,1.97,62.1
11800,47.4,1.96,62.2
11800,47.4,1.96,62.3
11800,47.5,1.96,62.4
11800,47.6,1.95,62.5
11700,47.7,1.94,62.6
11700,47.8,1.95,62.7
11700,47.9,1.95,62.8
11700,47.9,1.95,63
11700,48,1.94,63.1
11800,48.1,1.95,63.2
11800,48.2,1.96,63.3
11800,48.3,1.96,63.4
11800,48.4,1.96,63.5
11800,48.4,1.96,63.6
11800,48.5,1.96,63.7
11700,48.6,1.95,63.8
11700,48.7,1.95,63.9
11800,48.8,1.96,64.1
11900,48.9,1.98,64.2
12000,48.9,2,64.3
12100,49,2.01,64.4
12200,49.1,2.03,64.5
12200,49.2,2.03,64.6
12200,49.3,2.03,64.7
12100,49.4,2.02,64.8
12100,49.4,2.02,64.9
12100,49.5,2.01,65
12000,49.6,2,65.1
12000,49.7,1.99,65.3
12000,49.8,1.99,65.4
12000,49.9,1.99,65.5
11900,49.9,1.97,65.6
11800,50,1.96,65.7
11800,50.1,1.96,65.8
11800,50.2,1.96,65.9
11900,50.3,1.97,66
11900,50.4,1.97,66.1
11900,50.4,1.97,66.2
11800,50.5,1.96,66.3
11800,50.6,1.96,66.5
11800,50.7,1.96,66.6
11800,50.8,1.96,66.7
11900,50.9,1.97,66.8
11900,50.9,1.98,66.9
11900,51,1.98,67
11900,51.1,1.98,67.1
11800,51.2,1.97,67.2
11700,51.3,1.95,67.3
11600,51.4,1.94,67.4
11600,51.4,1.94,67.6
11700,51.5,1.94,67.7
11700,51.6,1.95,67.8
11800,51.7,1.95,67.9
11900,51.8,1.97,68
11900,51.9,1.98,68.1
12000,51.9,2,68.2
12100,52,2.01,68.3
12100,52.1,2.01,68.4
12000,52.2,2,68.5
12000,52.3,2,68.7
11900,52.4,1.99,68.8
11900,52.4,1.98,68.9
11800,52.5,1.97,69
11800,52.6,1.96,69.1
11800,52.7,1.96,69.2
11800,52.8,1.96,69.3
11800,52.9,1.96,69.4
11900,52.9,1.98,69.5
12000,53,1.99,69.6
12100,53.1,2.01,69.7
12200,53.2,2.02,69.9
12200,53.3,2.03,70
12200,53.4,2.03,70.1
12200,53.4,2.03,70.2
12200,53.5,2.02,70.3
12200,53.6,2.02,70.4
12100,53.7,2.01,70.5
12000,53.8,1.99,70.6
11800,53.9,1.97,70.7
11800,53.9,1.96,70.8
11700,54,1.95,70.9
11800,54.1,1.96,71.1
11800,54.2,1.96,71.2
11900,54.3,1.97,71.3
11900,54.4,1.98,71.4
12000,54.4,1.99,71.5
12000,54.5,2,71.6
12100,54.6,2.02,71.7
12200,54.7,2.02,71.8
12200,54.8,2.03,71.9
12200,54.9,2.02,72
12200,54.9,2.02,72.2
12100,55,2,72.3
12000,55.1,1.99,72.4
11900,55.2,1.97,72.5
11800,55.3,1.96,72.6
11700,55.4,1.94,72.7
11600,55.4,1.93,72.8
11600,55.5,1.92,72.9
11500,55.6,1.91,73
11500,55.7,1.92,73.1
11600,55.8,1.93,73.2
11700,55.9,1.94,73.4
11800,55.9,1.96,73.5
11900,56,1.98,73.6
12000,56.1,1.99,73.7
12000,56.2,2,73.8
12100,56.3,2.01,73.9
12100,56.4,2.01,74
12100,56.4,2.01,74.1
12000,56.5,1.99,74.2
11900,56.6,1.98,74.3
11800,56.7,1.96,74.4
11700,56.8,1.95,74.6
11700,56.9,1.94,74.7
11600,56.9,1.93,74.8
11600,57,1.92,74.9
11600,57.1,1.92,75
11600,57.2,1.92,75.1
11500,57.3,1.92,75.2
11500,57.4,1.92,75.3
11600,57.4,1.93,75.4
11600,57.5,1.93,75.5
11700,57.6,1.94,75.7
11700,57.7,1.94,75.8
11700,57.8,1.94,75.9
11700,57.9,1.94,76
11700,57.9,1.94,76.1
11500,58,1.91,76.2
11400,58.1,1.89,76.3
11000,58.2,1.84,76.4
10800,58.3,1.8,76.5
10600,58.4,1.76,76.6
10200,58.4,1.7,76.8
10000,58.5,1.67,76.9
9870,58.6,1.64,77
9710,58.7,1.61,77.1
9660,58.8,1.61,77.2
9640,58.9,1.6,77.3
9630,58.9,1.6,77.4
9570,59,1.59,77.5
9530,59.1,1.58,77.6
9540,59.2,1.59,77.7
9700,59.3,1.61,77.8
9850,59.4,1.64,77.9
10100,59.4,1.68,78.1
10400,59.5,1.72,78.2
10800,59.6,1.79,78.3
11200,59.7,1.86,78.4
11800,59.8,1.96,78.5
12400,59.9,2.05,78.6
13000,59.9,2.17,78.7
13600,60,2.27,78.8
14300,60.1,2.37,78.9
14900,60.2,2.48,79
15700,60.3,2.6,79.2
16300,60.4,2.71,79.3
17000,60.4,2.82,79.4
17500,60.5,2.92,79.5
18200,60.6,3.02,79.6
18700,60.7,3.11,79.7
19200,60.8,3.2,79.8
19700,60.9,3.27,79.9
20200,60.9,3.35,80
20500,61,3.42,80.1
21000,61.1,3.49,80.2
21400,61.2,3.56,80.4
21900,61.3,3.63,80.5
22200,61.3,3.7,80.6
22700,61.4,3.77,80.7
23000,61.5,3.83,80.8
23500,61.6,3.9,80.9
23800,61.7,3.96,81
24200,61.8,4.03,81.1
24600,61.8,4.09,81.2
25000,61.9,4.16,81.3
25300,62,4.21,81.4
25800,62.1,4.29,81.6
26100,62.2,4.34,81.7
26600,62.3,4.42,81.8
26900,62.3,4.47,81.9
27300,62.4,4.55,82
27700,62.5,4.6,82.1
28100,62.6,4.68,82.2
28500,62.7,4.73,82.3
28900,62.8,4.81,82.4
29300,62.8,4.87,82.5
29800,62.9,4.95,82.7
30100,63,5,82.8
25800,63,4.28,82.7
20600,62.9,3.42,82.6
14900,62.8,2.47,82.5
11800,62.8,1.97,82.4
8150,62.7,1.36,82.3
6080,62.6,1.01,82.2
4190,62.5,0.697,82.1
2880,62.4,0.48,82
2020,62.3,0.336,81.9
1290,62.2,0.215,81.8
815,62.2,0.136,81.6
477,62.1,0.0793,81.5
330,62,0.0549,81.5